[2024-04-17T07:47:45.441+0000] {local_task_job_runner.py:120} INFO - ::group::Pre task execution logs
[2024-04-17T07:47:45.488+0000] {taskinstance.py:2073} INFO - Dependencies all met for dep_context=non-requeueable deps ti=<TaskInstance: sales_fact.sales_fact scheduled__2024-04-16T00:00:00+00:00 [queued]>
[2024-04-17T07:47:45.499+0000] {taskinstance.py:2073} INFO - Dependencies all met for dep_context=requeueable deps ti=<TaskInstance: sales_fact.sales_fact scheduled__2024-04-16T00:00:00+00:00 [queued]>
[2024-04-17T07:47:45.500+0000] {taskinstance.py:2303} INFO - Starting attempt 1 of 1
[2024-04-17T07:47:45.536+0000] {taskinstance.py:2327} INFO - Executing <Task(PythonOperator): sales_fact> on 2024-04-16 00:00:00+00:00
[2024-04-17T07:47:45.556+0000] {warnings.py:110} WARNING - /home/***/.local/lib/python3.12/site-packages/***/task/task_runner/standard_task_runner.py:61: DeprecationWarning: This process (pid=283) is multi-threaded, use of fork() may lead to deadlocks in the child.
  pid = os.fork()

[2024-04-17T07:47:45.559+0000] {standard_task_runner.py:63} INFO - Started process 285 to run task
[2024-04-17T07:47:45.559+0000] {standard_task_runner.py:90} INFO - Running: ['***', 'tasks', 'run', 'sales_fact', 'sales_fact', 'scheduled__2024-04-16T00:00:00+00:00', '--job-id', '11', '--raw', '--subdir', 'DAGS_FOLDER/sales_fact.py', '--cfg-path', '/tmp/tmpntpx70tc']
[2024-04-17T07:47:45.567+0000] {standard_task_runner.py:91} INFO - Job 11: Subtask sales_fact
[2024-04-17T07:47:45.666+0000] {task_command.py:426} INFO - Running <TaskInstance: sales_fact.sales_fact scheduled__2024-04-16T00:00:00+00:00 [running]> on host bfeb90cb790e
[2024-04-17T07:47:45.773+0000] {taskinstance.py:2644} INFO - Exporting env vars: AIRFLOW_CTX_DAG_OWNER='alexeevkv' AIRFLOW_CTX_DAG_ID='sales_fact' AIRFLOW_CTX_TASK_ID='sales_fact' AIRFLOW_CTX_EXECUTION_DATE='2024-04-16T00:00:00+00:00' AIRFLOW_CTX_TRY_NUMBER='1' AIRFLOW_CTX_DAG_RUN_ID='scheduled__2024-04-16T00:00:00+00:00'
[2024-04-17T07:47:45.775+0000] {taskinstance.py:430} INFO - ::endgroup::
[2024-04-17T07:47:45.982+0000] {taskinstance.py:441} INFO - ::group::Post task execution logs
[2024-04-17T07:47:45.983+0000] {taskinstance.py:2890} ERROR - Task failed with exception
Traceback (most recent call last):
  File "/home/airflow/.local/lib/python3.12/site-packages/airflow/models/taskinstance.py", line 465, in _execute_task
    result = _execute_callable(context=context, **execute_callable_kwargs)
             ^^^^^^^^^^^^^^^^^^^^^^^^^^^^^^^^^^^^^^^^^^^^^^^^^^^^^^^^^^^^^
  File "/home/airflow/.local/lib/python3.12/site-packages/airflow/models/taskinstance.py", line 432, in _execute_callable
    return execute_callable(context=context, **execute_callable_kwargs)
           ^^^^^^^^^^^^^^^^^^^^^^^^^^^^^^^^^^^^^^^^^^^^^^^^^^^^^^^^^^^^
  File "/home/airflow/.local/lib/python3.12/site-packages/airflow/models/baseoperator.py", line 400, in wrapper
    return func(self, *args, **kwargs)
           ^^^^^^^^^^^^^^^^^^^^^^^^^^^
  File "/home/airflow/.local/lib/python3.12/site-packages/airflow/operators/python.py", line 235, in execute
    return_value = self.execute_callable()
                   ^^^^^^^^^^^^^^^^^^^^^^^
  File "/home/airflow/.local/lib/python3.12/site-packages/airflow/operators/python.py", line 252, in execute_callable
    return self.python_callable(*self.op_args, **self.op_kwargs)
           ^^^^^^^^^^^^^^^^^^^^^^^^^^^^^^^^^^^^^^^^^^^^^^^^^^^^^
  File "/opt/airflow/dags/sales_fact.py", line 33, in sales_fact
    conn = psycopg2.connect(
           ^^^^^^^^^^^^^^^^^
  File "/home/airflow/.local/lib/python3.12/site-packages/psycopg2/__init__.py", line 122, in connect
    conn = _connect(dsn, connection_factory=connection_factory, **kwasync)
           ^^^^^^^^^^^^^^^^^^^^^^^^^^^^^^^^^^^^^^^^^^^^^^^^^^^^^^^^^^^^^^^
psycopg2.OperationalError: connection to server at "95.131.149.21", port 5432 failed: FATAL:  password authentication failed for user "dep17"
connection to server at "95.131.149.21", port 5432 failed: FATAL:  password authentication failed for user "dep17"

[2024-04-17T07:47:46.008+0000] {taskinstance.py:1205} INFO - Marking task as FAILED. dag_id=sales_fact, task_id=sales_fact, execution_date=20240416T000000, start_date=20240417T074745, end_date=20240417T074746
[2024-04-17T07:47:46.029+0000] {standard_task_runner.py:110} ERROR - Failed to execute job 11 for task sales_fact (connection to server at "95.131.149.21", port 5432 failed: FATAL:  password authentication failed for user "dep17"
connection to server at "95.131.149.21", port 5432 failed: FATAL:  password authentication failed for user "dep17"
; 285)
[2024-04-17T07:47:46.058+0000] {local_task_job_runner.py:240} INFO - Task exited with return code 1
[2024-04-17T07:47:46.091+0000] {taskinstance.py:3482} INFO - 0 downstream tasks scheduled from follow-on schedule check
[2024-04-17T07:47:46.097+0000] {local_task_job_runner.py:222} INFO - ::endgroup::
