[2024-04-17T07:47:51.246+0000] {local_task_job_runner.py:120} INFO - ::group::Pre task execution logs
[2024-04-17T07:47:51.282+0000] {taskinstance.py:2073} INFO - Dependencies all met for dep_context=non-requeueable deps ti=<TaskInstance: sales_fact.sales_fact manual__2024-04-17T07:47:37.423820+00:00 [queued]>
[2024-04-17T07:47:51.292+0000] {taskinstance.py:2073} INFO - Dependencies all met for dep_context=requeueable deps ti=<TaskInstance: sales_fact.sales_fact manual__2024-04-17T07:47:37.423820+00:00 [queued]>
[2024-04-17T07:47:51.293+0000] {taskinstance.py:2303} INFO - Starting attempt 1 of 1
[2024-04-17T07:47:51.313+0000] {taskinstance.py:2327} INFO - Executing <Task(PythonOperator): sales_fact> on 2024-04-17 07:47:37.423820+00:00
[2024-04-17T07:47:51.321+0000] {warnings.py:110} WARNING - /home/***/.local/lib/python3.12/site-packages/***/task/task_runner/standard_task_runner.py:61: DeprecationWarning: This process (pid=286) is multi-threaded, use of fork() may lead to deadlocks in the child.
  pid = os.fork()

[2024-04-17T07:47:51.324+0000] {standard_task_runner.py:63} INFO - Started process 288 to run task
[2024-04-17T07:47:51.324+0000] {standard_task_runner.py:90} INFO - Running: ['***', 'tasks', 'run', 'sales_fact', 'sales_fact', 'manual__2024-04-17T07:47:37.423820+00:00', '--job-id', '12', '--raw', '--subdir', 'DAGS_FOLDER/sales_fact.py', '--cfg-path', '/tmp/tmp6afu48xt']
[2024-04-17T07:47:51.328+0000] {standard_task_runner.py:91} INFO - Job 12: Subtask sales_fact
[2024-04-17T07:47:51.393+0000] {task_command.py:426} INFO - Running <TaskInstance: sales_fact.sales_fact manual__2024-04-17T07:47:37.423820+00:00 [running]> on host bfeb90cb790e
[2024-04-17T07:47:51.513+0000] {taskinstance.py:2644} INFO - Exporting env vars: AIRFLOW_CTX_DAG_OWNER='alexeevkv' AIRFLOW_CTX_DAG_ID='sales_fact' AIRFLOW_CTX_TASK_ID='sales_fact' AIRFLOW_CTX_EXECUTION_DATE='2024-04-17T07:47:37.423820+00:00' AIRFLOW_CTX_TRY_NUMBER='1' AIRFLOW_CTX_DAG_RUN_ID='manual__2024-04-17T07:47:37.423820+00:00'
[2024-04-17T07:47:51.515+0000] {taskinstance.py:430} INFO - ::endgroup::
[2024-04-17T07:47:51.634+0000] {taskinstance.py:441} INFO - ::group::Post task execution logs
[2024-04-17T07:47:51.635+0000] {taskinstance.py:2890} ERROR - Task failed with exception
Traceback (most recent call last):
  File "/home/airflow/.local/lib/python3.12/site-packages/airflow/models/taskinstance.py", line 465, in _execute_task
    result = _execute_callable(context=context, **execute_callable_kwargs)
             ^^^^^^^^^^^^^^^^^^^^^^^^^^^^^^^^^^^^^^^^^^^^^^^^^^^^^^^^^^^^^
  File "/home/airflow/.local/lib/python3.12/site-packages/airflow/models/taskinstance.py", line 432, in _execute_callable
    return execute_callable(context=context, **execute_callable_kwargs)
           ^^^^^^^^^^^^^^^^^^^^^^^^^^^^^^^^^^^^^^^^^^^^^^^^^^^^^^^^^^^^
  File "/home/airflow/.local/lib/python3.12/site-packages/airflow/models/baseoperator.py", line 400, in wrapper
    return func(self, *args, **kwargs)
           ^^^^^^^^^^^^^^^^^^^^^^^^^^^
  File "/home/airflow/.local/lib/python3.12/site-packages/airflow/operators/python.py", line 235, in execute
    return_value = self.execute_callable()
                   ^^^^^^^^^^^^^^^^^^^^^^^
  File "/home/airflow/.local/lib/python3.12/site-packages/airflow/operators/python.py", line 252, in execute_callable
    return self.python_callable(*self.op_args, **self.op_kwargs)
           ^^^^^^^^^^^^^^^^^^^^^^^^^^^^^^^^^^^^^^^^^^^^^^^^^^^^^
  File "/opt/airflow/dags/sales_fact.py", line 33, in sales_fact
    conn = psycopg2.connect(
           ^^^^^^^^^^^^^^^^^
  File "/home/airflow/.local/lib/python3.12/site-packages/psycopg2/__init__.py", line 122, in connect
    conn = _connect(dsn, connection_factory=connection_factory, **kwasync)
           ^^^^^^^^^^^^^^^^^^^^^^^^^^^^^^^^^^^^^^^^^^^^^^^^^^^^^^^^^^^^^^^
psycopg2.OperationalError: connection to server at "95.131.149.21", port 5432 failed: FATAL:  password authentication failed for user "dep17"
connection to server at "95.131.149.21", port 5432 failed: FATAL:  password authentication failed for user "dep17"

[2024-04-17T07:47:51.653+0000] {taskinstance.py:1205} INFO - Marking task as FAILED. dag_id=sales_fact, task_id=sales_fact, execution_date=20240417T074737, start_date=20240417T074751, end_date=20240417T074751
[2024-04-17T07:47:51.667+0000] {standard_task_runner.py:110} ERROR - Failed to execute job 12 for task sales_fact (connection to server at "95.131.149.21", port 5432 failed: FATAL:  password authentication failed for user "dep17"
connection to server at "95.131.149.21", port 5432 failed: FATAL:  password authentication failed for user "dep17"
; 288)
[2024-04-17T07:47:51.700+0000] {local_task_job_runner.py:240} INFO - Task exited with return code 1
[2024-04-17T07:47:51.724+0000] {taskinstance.py:3482} INFO - 0 downstream tasks scheduled from follow-on schedule check
[2024-04-17T07:47:51.731+0000] {local_task_job_runner.py:222} INFO - ::endgroup::
